Workbook

Sheet Lab Analysis
A1: LAB ANALYSIS - UREA AGL
C2: REACTOR (U-DC101) | G2: STRIPPER (U-DA 101) | K2: HPD (U-DA 201) | O2: LPD (U-DA 202) | S2: HPA (U-EA 401) | W2: LPA (U-EA 402) | AA2: REFLUX DRUM (U-FA 509) | AE2: WASHING COLOUMN (U-DA401) | AI2: SUCTION (FA-501) (U-GA501) | AM2: DESORBER OUTLET (DA-501) | AQ2: UREA SOLUTION TANK (U-FA 201)
A3: Date | B3: Load | C3: NH3 % 31.13 | D3: CO2 % 17.39 | E3: Urea % 32.74 | F3: H2O% | G3: NH3 % 8.59 | H3: CO2 % 10.87 | I3: Urea % 53.71 | J3: H2O% | K3: NH3 % 14.94 | L3: CO2 % 9.77 | M3: Urea% 49.83 | N3: H2O% | O3: NH3 % 1.62 | P3: CO2 % 0.82 | Q3: Urea % 68.22 | R3: H2O% | S3: NH3 % 37.55 | T3: CO2 % 40.79 | U3: Urea % --- | V3: H2O% | W3: NH3 % 32.27 | X3: CO2 % 36.45 | Y3: Urea % --- | Z3: H2O% | AA3: NH3 % 27.23 | AB3: CO2 % 20.09 | AC3: Urea % -- | AD3: H2O% | AE3: NH3 % 21.40 | AF3: CO2 % 7.82 | AG3: Urea% -- | AH3: H2O% | AI3: NH3 % 5.04 | AJ3: CO2 % 2.17 | AK3: Urea% 1.89 | AL3: H2O% | AM3: NH3 ppm 5.0 | AN3: CO2 ppm | AO3: Urea ppm 5.0 | AP3: H2O% | AQ3: NH3 % 0.46 | AR3: CO2 % 0.31 | AS3: Urea % 72.39 | AT3: H2O%
A4: 45819 | C4: 30.02 | D4: 18.58 | E4: 32.37 | F4: =100-SUM(C4:E4) -> 19.03 | J4: =100-SUM(G4:I4) -> 100 | N4: =100-SUM(K4:M4) -> 100 | R4: =100-SUM(O4:Q4) -> 100 | V4: =100-SUM(S4:U4) -> 100 | Z4: =100-SUM(W4:Y4) -> 100 | AD4: =100-SUM(AA4:AC4) -> 100 | AH4: =100-SUM(AE4:AG4) -> 100 | AL4: =100-SUM(AI4:AK4) -> 100 | AP4: =100-SUM(AM4:AO4) -> 100 | AT4: =100-SUM(AQ4:AS4) -> 100
A5: 45820 | C5: 30.14 | D5: 18.93 | E5: 31.89 | F5: =100-SUM(C5:E5) -> 19.04 | G5: 10.82 | H5: 11.01 | I5: 50.37 | J5: =100-SUM(G5:I5) -> 27.8 | K5: 16.58 | L5: 12.65 | M5: 43.43 | N5: =100-SUM(K5:M5) -> 27.34 | O5: 0.53 | P5: 0.19 | Q5: 63 | R5: =100-SUM(O5:Q5) -> 36.28 | S5: 37.4 | T5: 39.89 | U5: - | V5: =100-SUM(S5:U5) -> 22.71 | W5: 34.86 | X5: 34.69 | Y5: - | Z5: =100-SUM(W5:Y5) -> 30.45 | AA5: 29.19 | AB5: 10.91 | AC5: - | AD5: =100-SUM(AA5:AC5) -> 59.9 | AE5: 13.63 | AF5: 3.44 | AG5: - | AH5: =100-SUM(AE5:AG5) -> 82.93 | AI5: 5.81 | AJ5: 1.6 | AK5: 1.31 | AL5: =100-SUM(AI5:AK5) -> 91.28 | AM5: 1.7 | AN5: - | AO5: - | AP5: =100-SUM(AM5:AO5) -> 98.3 | AQ5: 0.49 | AR5: 0.21 | AS5: 71 | AT5: =100-SUM(AQ5:AS5) -> 28.3
A6: 45821 | C6: 30.17 | D6: 19.32 | E6: 31.64 | F6: =100-SUM(C6:E6) -> 18.87 | J6: =100-SUM(G6:I6) -> 100 | N6: =100-SUM(K6:M6) -> 100 | R6: =100-SUM(O6:Q6) -> 100 | V6: =100-SUM(S6:U6) -> 100 | Z6: =100-SUM(W6:Y6) -> 100 | AD6: =100-SUM(AA6:AC6) -> 100 | AE6: 15.32 | AF6: 3.14 | AH6: =100-SUM(AE6:AG6) -> 81.54 | AL6: =100-SUM(AI6:AK6) -> 100 | AP6: =100-SUM(AM6:AO6) -> 100 | AT6: =100-SUM(AQ6:AS6) -> 100
A7: 45822 | F7: =100-SUM(C7:E7) -> 100 | J7: =100-SUM(G7:I7) -> 100 | N7: =100-SUM(K7:M7) -> 100 | R7: =100-SUM(O7:Q7) -> 100 | V7: =100-SUM(S7:U7) -> 100 | Z7: =100-SUM(W7:Y7) -> 100 | AD7: =100-SUM(AA7:AC7) -> 100 | AH7: =100-SUM(AE7:AG7) -> 100 | AL7: =100-SUM(AI7:AK7) -> 100 | AP7: =100-SUM(AM7:AO7) -> 100 | AT7: =100-SUM(AQ7:AS7) -> 100
A8: 45823 | F8: =100-SUM(C8:E8) -> 100 | J8: =100-SUM(G8:I8) -> 100 | N8: =100-SUM(K8:M8) -> 100 | R8: =100-SUM(O8:Q8) -> 100 | V8: =100-SUM(S8:U8) -> 100 | Z8: =100-SUM(W8:Y8) -> 100 | AD8: =100-SUM(AA8:AC8) -> 100 | AH8: =100-SUM(AE8:AG8) -> 100 | AL8: =100-SUM(AI8:AK8) -> 100 | AP8: =100-SUM(AM8:AO8) -> 100 | AT8: =100-SUM(AQ8:AS8) -> 100
A9: 45824 | C9: 30.78 | D9: 19.96 | E9: 31.24 | F9: =100-SUM(C9:E9) -> 18.02 | G9: 10.91 | H9: 11.01 | I9: 49.22 | J9: =100-SUM(G9:I9) -> 28.86 | K9: 16.43 | L9: 12.92 | M9: 43.77 | N9: =100-SUM(K9:M9) -> 26.88 | O9: 0.56 | P9: 0.21 | Q9: 64 | R9: =100-SUM(O9:Q9) -> 35.23 | S9: 36.15 | T9: 40.29 | U9: - | V9: =100-SUM(S9:U9) -> 23.56 | W9: 34.12 | X9: 33.88 | Y9: - | Z9: =100-SUM(W9:Y9) -> 32 | AA9: 29.26 | AB9: 10.83 | AC9: - | AD9: =100-SUM(AA9:AC9) -> 59.91 | AE9: 16.61 | AF9: 3.46 | AG9: - | AH9: =100-SUM(AE9:AG9) -> 79.93 | AI9: 6.8 | AJ9: 1.49 | AK9: 1.36 | AL9: =100-SUM(AI9:AK9) -> 90.35 | AM9: 1.7 | AN9: - | AO9: - | AP9: =100-SUM(AM9:AO9) -> 98.3 | AQ9: 0.53 | AR9: 0.2 | AS9: 71 | AT9: =100-SUM(AQ9:AS9) -> 28.27
A10: 45825 | C10: 30.53 | D10: 19.49 | E10: 31.77 | F10: =100-SUM(C10:E10) -> 18.21 | J10: =100-SUM(G10:I10) -> 100 | N10: =100-SUM(K10:M10) -> 100 | R10: =100-SUM(O10:Q10) -> 100 | V10: =100-SUM(S10:U10) -> 100 | Z10: =100-SUM(W10:Y10) -> 100 | AD10: =100-SUM(AA10:AC10) -> 100 | AH10: =100-SUM(AE10:AG10) -> 100 | AL10: =100-SUM(AI10:AK10) -> 100 | AP10: =100-SUM(AM10:AO10) -> 100 | AT10: =100-SUM(AQ10:AS10) -> 100
A11: 45826 | C11: 29.68 | D11: 19.59 | E11: 31.66 | F11: =100-SUM(C11:E11) -> 19.07 | J11: =100-SUM(G11:I11) -> 100 | N11: =100-SUM(K11:M11) -> 100 | R11: =100-SUM(O11:Q11) -> 100 | V11: =100-SUM(S11:U11) -> 100 | Z11: =100-SUM(W11:Y11) -> 100 | AD11: =100-SUM(AA11:AC11) -> 100 | AH11: =100-SUM(AE11:AG11) -> 100 | AL11: =100-SUM(AI11:AK11) -> 100 | AP11: =100-SUM(AM11:AO11) -> 100 | AT11: =100-SUM(AQ11:AS11) -> 100
A12: 45827 | C12: 31.41 | D12: 18.51 | E12: 30.87 | F12: =100-SUM(C12:E12) -> 19.21 | G12: 10.24 | H12: 10.58 | I12: 50.86 | J12: =100-SUM(G12:I12) -> 28.32 | K12: 17.05 | L12: 13.13 | M12: 44.9 | N12: =100-SUM(K12:M12) -> 24.92 | O12: 0.56 | P12: 0.21 | Q12: 66 | R12: =100-SUM(O12:Q12) -> 33.23 | S12: 37.45 | T12: 40.48 | U12: - | V12: =100-SUM(S12:U12) -> 22.07 | W12: 33.94 | X12: 34.26 | Y12: - | Z12: =100-SUM(W12:Y12) -> 31.8 | AA12: 28.63 | AB12: 10.04 | AC12: - | AD12: =100-SUM(AA12:AC12) -> 61.33 | AE12: 17.03 | AF12: 3.33 | AG12: - | AH12: =100-SUM(AE12:AG12) -> 79.64 | AI12: 6.19 | AJ12: 1.57 | AK12: 1.24 | AL12: =100-SUM(AI12:AK12) -> 91 | AM12: 2.38 | AN12: - | AO12: - | AP12: =100-SUM(AM12:AO12) -> 97.62 | AQ12: 0.48 | AR12: 0.19 | AS12: 71 | AT12: =100-SUM(AQ12:AS12) -> 28.33
A13: 45828 | C13: 30.35 | D13: 19.6 | E13: 31.47 | F13: =100-SUM(C13:E13) -> 18.58 | J13: =100-SUM(G13:I13) -> 100 | N13: =100-SUM(K13:M13) -> 100 | R13: =100-SUM(O13:Q13) -> 100 | V13: =100-SUM(S13:U13) -> 100 | Z13: =100-SUM(W13:Y13) -> 100 | AD13: =100-SUM(AA13:AC13) -> 100 | AH13: =100-SUM(AE13:AG13) -> 100 | AL13: =100-SUM(AI13:AK13) -> 100 | AP13: =100-SUM(AM13:AO13) -> 100 | AT13: =100-SUM(AQ13:AS13) -> 100
A14: 45829 | F14: =100-SUM(C14:E14) -> 100 | J14: =100-SUM(G14:I14) -> 100 | N14: =100-SUM(K14:M14) -> 100 | R14: =100-SUM(O14:Q14) -> 100 | V14: =100-SUM(S14:U14) -> 100 | Z14: =100-SUM(W14:Y14) -> 100 | AD14: =100-SUM(AA14:AC14) -> 100 | AH14: =100-SUM(AE14:AG14) -> 100 | AL14: =100-SUM(AI14:AK14) -> 100 | AP14: =100-SUM(AM14:AO14) -> 100 | AT14: =100-SUM(AQ14:AS14) -> 100
A15: 45830 | F15: =100-SUM(C15:E15) -> 100 | J15: =100-SUM(G15:I15) -> 100 | N15: =100-SUM(K15:M15) -> 100 | R15: =100-SUM(O15:Q15) -> 100 | V15: =100-SUM(S15:U15) -> 100 | Z15: =100-SUM(W15:Y15) -> 100 | AD15: =100-SUM(AA15:AC15) -> 100 | AH15: =100-SUM(AE15:AG15) -> 100 | AL15: =100-SUM(AI15:AK15) -> 100 | AP15: =100-SUM(AM15:AO15) -> 100 | AT15: =100-SUM(AQ15:AS15) -> 100
A16: 45831 | C16: 31.78 | D16: 19.96 | E16: 31.28 | F16: =100-SUM(C16:E16) -> 16.98 | G16: 10.23 | H16: 10.72 | I16: 49.92 | J16: =100-SUM(G16:I16) -> 29.13 | K16: 17.09 | L16: 13.07 | M16: 44.3 | N16: =100-SUM(K16:M16) -> 25.54 | R16: =100-SUM(O16:Q16) -> 100 | S16: 37.28 | T16: 39.12 | U16: 0 | V16: =100-SUM(S16:U16) -> 23.6 | Z16: =100-SUM(W16:Y16) -> 100 | AA16: 29.32 | AB16: 10.68 | AC16: - | AD16: =100-SUM(AA16:AC16) -> 60 | AE16: 16.82 | AF16: 3.52 | AG16: - | AH16: =100-SUM(AE16:AG16) -> 79.66 | AI16: 6.49 | AJ16: 1.64 | AK16: 1.32 | AL16: =100-SUM(AI16:AK16) -> 90.55 | AM16: 2.24 | AN16: - | AO16: - | AP16: =100-SUM(AM16:AO16) -> 97.76 | AQ16: 0.51 | AR16: 0.22 | AS16: 70 | AT16: =100-SUM(AQ16:AS16) -> 29.27
A17: 45832 | C17: 30.69 | D17: 19.12 | E17: 31.67 | F17: =100-SUM(C17:E17) -> 18.52 | J17: =100-SUM(G17:I17) -> 100 | N17: =100-SUM(K17:M17) -> 100 | R17: =100-SUM(O17:Q17) -> 100 | V17: =100-SUM(S17:U17) -> 100 | Z17: =100-SUM(W17:Y17) -> 100 | AD17: =100-SUM(AA17:AC17) -> 100 | AH17: =100-SUM(AE17:AG17) -> 100 | AL17: =100-SUM(AI17:AK17) -> 100 | AP17: =100-SUM(AM17:AO17) -> 100 | AT17: =100-SUM(AQ17:AS17) -> 100
A18: 45833 | C18: 29.82 | D18: 18.62 | E18: 31.19 | F18: =100-SUM(C18:E18) -> 20.37 | J18: =100-SUM(G18:I18) -> 100 | N18: =100-SUM(K18:M18) -> 100 | R18: =100-SUM(O18:Q18) -> 100 | V18: =100-SUM(S18:U18) -> 100 | Z18: =100-SUM(W18:Y18) -> 100 | AD18: =100-SUM(AA18:AC18) -> 100 | AH18: =100-SUM(AE18:AG18) -> 100 | AL18: =100-SUM(AI18:AK18) -> 100 | AP18: =100-SUM(AM18:AO18) -> 100 | AT18: =100-SUM(AQ18:AS18) -> 100
A19: 45834 | C19: 31.09 | D19: 18.97 | E19: 30.92 | F19: =100-SUM(C19:E19) -> 19.02 | G19: 10.49 | H19: 10.49 | I19: 50.51 | J19: =100-SUM(G19:I19) -> 28.51 | K19: 16.87 | L19: 13.41 | M19: 44.22 | N19: =100-SUM(K19:M19) -> 25.5 | O19: 0.67 | P19: 0.26 | Q19: 62 | R19: =100-SUM(O19:Q19) -> 37.07 | S19: 36.34 | T19: 38.97 | U19: 0 | V19: =100-SUM(S19:U19) -> 24.69 | W19: 33.15 | X19: 33.92 | Y19: 0 | Z19: =100-SUM(W19:Y19) -> 32.93 | AA19: 29.97 | AB19: 10.83 | AC19: - | AD19: =100-SUM(AA19:AC19) -> 59.2 | AE19: 15.64 | AF19: 3.29 | AG19: - | AH19: =100-SUM(AE19:AG19) -> 81.07 | AI19: 6.29 | AJ19: 1.51 | AK19: 1.26 | AL19: =100-SUM(AI19:AK19) -> 90.94 | AM19: 2.21 | AN19: - | AO19: - | AP19: =100-SUM(AM19:AO19) -> 97.79 | AQ19: 0.53 | AR19: 0.21 | AS19: 71 | AT19: =100-SUM(AQ19:AS19) -> 28.26
A20: 45835 | C20: 30.09 | D20: 19.04 | E20: 30.75 | F20: =100-SUM(C20:E20) -> 20.12 | J20: =100-SUM(G20:I20) -> 100 | N20: =100-SUM(K20:M20) -> 100 | R20: =100-SUM(O20:Q20) -> 100 | V20: =100-SUM(S20:U20) -> 100 | Z20: =100-SUM(W20:Y20) -> 100 | AD20: =100-SUM(AA20:AC20) -> 100 | AH20: =100-SUM(AE20:AG20) -> 100 | AL20: =100-SUM(AI20:AK20) -> 100 | AP20: =100-SUM(AM20:AO20) -> 100 | AT20: =100-SUM(AQ20:AS20) -> 100
A22: 45836 | F22: =100-SUM(C22:E22) -> 100 | J22: =100-SUM(G22:I22) -> 100 | N22: =100-SUM(K22:M22) -> 100 | R22: =100-SUM(O22:Q22) -> 100 | V22: =100-SUM(S22:U22) -> 100 | Z22: =100-SUM(W22:Y22) -> 100 | AD22: =100-SUM(AA22:AC22) -> 100 | AH22: =100-SUM(AE22:AG22) -> 100 | AL22: =100-SUM(AI22:AK22) -> 100 | AP22: =100-SUM(AM22:AO22) -> 100 | AT22: =100-SUM(AQ22:AS22) -> 100
A23: 45837 | F23: =100-SUM(C23:E23) -> 100 | J23: =100-SUM(G23:I23) -> 100 | N23: =100-SUM(K23:M23) -> 100 | R23: =100-SUM(O23:Q23) -> 100 | V23: =100-SUM(S23:U23) -> 100 | Z23: =100-SUM(W23:Y23) -> 100 | AD23: =100-SUM(AA23:AC23) -> 100 | AH23: =100-SUM(AE23:AG23) -> 100 | AL23: =100-SUM(AI23:AK23) -> 100 | AP23: =100-SUM(AM23:AO23) -> 100 | AT23: =100-SUM(AQ23:AS23) -> 100
A24: 45838 | C24: 31.07 | D24: 19.3 | E24: 30.96 | F24: =100-SUM(C24:E24) -> 18.67 | G24: 10.18 | H24: 10.53 | I24: 49.94 | J24: =100-SUM(G24:I24) -> 29.35 | K24: 16.92 | L24: 13.07 | M24: 44.78 | N24: =100-SUM(K24:M24) -> 25.23 | O24: 0.54 | P24: 0.22 | Q24: 62 | R24: =100-SUM(O24:Q24) -> 37.24 | S24: 36.43 | T24: 39.76 | U24: 0 | V24: =100-SUM(S24:U24) -> 23.81 | W24: 33.58 | X24: 33.92 | Y24: 0 | Z24: =100-SUM(W24:Y24) -> 32.5 | AA24: 28.98 | AB24: 13.31 | AC24: - | AD24: =100-SUM(AA24:AC24) -> 57.71 | AE24: 15.37 | AF24: 3.36 | AG24: - | AH24: =100-SUM(AE24:AG24) -> 81.27 | AI24: 4.52 | AJ24: 1.35 | AK24: 1.26 | AL24: =100-SUM(AI24:AK24) -> 92.87 | AM24: 2.04 | AN24: - | AO24: - | AP24: =100-SUM(AM24:AO24) -> 97.96 | AQ24: 0.46 | AR24: 0.19 | AS24: 70 | AT24: =100-SUM(AQ24:AS24) -> 29.35
A25: 45839 | C25: 29.98 | D25: 19.11 | E25: 31.2 | F25: =100-SUM(C25:E25) -> 19.71 | J25: =100-SUM(G25:I25) -> 100 | N25: =100-SUM(K25:M25) -> 100 | R25: =100-SUM(O25:Q25) -> 100 | V25: =100-SUM(S25:U25) -> 100 | Z25: =100-SUM(W25:Y25) -> 100 | AD25: =100-SUM(AA25:AC25) -> 100 | AH25: =100-SUM(AE25:AG25) -> 100 | AL25: =100-SUM(AI25:AK25) -> 100 | AP25: =100-SUM(AM25:AO25) -> 100 | AT25: =100-SUM(AQ25:AS25) -> 100
A26: 45840 | C26: 29.92 | D26: 19.75 | E26: 31.44 | F26: =100-SUM(C26:E26) -> 18.89 | J26: =100-SUM(G26:I26) -> 100 | N26: =100-SUM(K26:M26) -> 100 | R26: =100-SUM(O26:Q26) -> 100 | V26: =100-SUM(S26:U26) -> 100 | Z26: =100-SUM(W26:Y26) -> 100 | AD26: =100-SUM(AA26:AC26) -> 100 | AH26: =100-SUM(AE26:AG26) -> 100 | AL26: =100-SUM(AI26:AK26) -> 100 | AP26: =100-SUM(AM26:AO26) -> 100 | AT26: =100-SUM(AQ26:AS26) -> 100
A27: 45841 | C27: 30.89 | D27: 19.66 | E27: 31.68 | F27: =100-SUM(C27:E27) -> 17.77 | G27: 9.94 | H27: 10.41 | I27: 50.19 | J27: =100-SUM(G27:I27) -> 29.46 | K27: 16.92 | L27: 12.98 | M27: 44.91 | N27: =100-SUM(K27:M27) -> 25.19 | O27: 0.61 | P27: 0.23 | Q27: 61 | R27: =100-SUM(O27:Q27) -> 38.16 | S27: 36.93 | T27: 39.89 | U27: 0 | V27: =100-SUM(S27:U27) -> 23.18 | W27: 33.72 | X27: 34.07 | Y27: 0 | Z27: =100-SUM(W27:Y27) -> 32.21 | AA27: 28.61 | AB27: 13.16 | AC27: - | AD27: =100-SUM(AA27:AC27) -> 58.23 | AE27: 17.13 | AF27: 3.84 | AG27: - | AH27: =100-SUM(AE27:AG27) -> 79.03 | AI27: 6.26 | AJ27: 1.39 | AK27: 1.24 | AL27: =100-SUM(AI27:AK27) -> 91.11 | AM27: 3.06 | AN27: - | AO27: - | AP27: =100-SUM(AM27:AO27) -> 96.94 | AQ27: 0.44 | AR27: 0.18 | AS27: 70 | AT27: =100-SUM(AQ27:AS27) -> 29.38
A28: 45842 | C28: 31.89 | D28: 18.91 | E28: 31.97 | F28: =100-SUM(C28:E28) -> 17.23 | J28: =100-SUM(G28:I28) -> 100 | N28: =100-SUM(K28:M28) -> 100 | R28: =100-SUM(O28:Q28) -> 100 | V28: =100-SUM(S28:U28) -> 100 | Z28: =100-SUM(W28:Y28) -> 100 | AD28: =100-SUM(AA28:AC28) -> 100 | AH28: =100-SUM(AE28:AG28) -> 100 | AL28: =100-SUM(AI28:AK28) -> 100 | AP28: =100-SUM(AM28:AO28) -> 100 | AT28: =100-SUM(AQ28:AS28) -> 100
A29: 45843 | F29: =100-SUM(C29:E29) -> 100 | J29: =100-SUM(G29:I29) -> 100 | N29: =100-SUM(K29:M29) -> 100 | R29: =100-SUM(O29:Q29) -> 100 | V29: =100-SUM(S29:U29) -> 100 | Z29: =100-SUM(W29:Y29) -> 100 | AD29: =100-SUM(AA29:AC29) -> 100 | AH29: =100-SUM(AE29:AG29) -> 100 | AL29: =100-SUM(AI29:AK29) -> 100 | AP29: =100-SUM(AM29:AO29) -> 100 | AT29: =100-SUM(AQ29:AS29) -> 100
A30: 45844 | F30: =100-SUM(C30:E30) -> 100 | J30: =100-SUM(G30:I30) -> 100 | N30: =100-SUM(K30:M30) -> 100 | R30: =100-SUM(O30:Q30) -> 100 | V30: =100-SUM(S30:U30) -> 100 | Z30: =100-SUM(W30:Y30) -> 100 | AD30: =100-SUM(AA30:AC30) -> 100 | AH30: =100-SUM(AE30:AG30) -> 100 | AL30: =100-SUM(AI30:AK30) -> 100 | AP30: =100-SUM(AM30:AO30) -> 100 | AT30: =100-SUM(AQ30:AS30) -> 100
A31: 45845 | F31: =100-SUM(C31:E31) -> 100 | J31: =100-SUM(G31:I31) -> 100 | N31: =100-SUM(K31:M31) -> 100 | R31: =100-SUM(O31:Q31) -> 100 | V31: =100-SUM(S31:U31) -> 100 | Z31: =100-SUM(W31:Y31) -> 100 | AD31: =100-SUM(AA31:AC31) -> 100 | AH31: =100-SUM(AE31:AG31) -> 100 | AL31: =100-SUM(AI31:AK31) -> 100 | AP31: =100-SUM(AM31:AO31) -> 100 | AT31: =100-SUM(AQ31:AS31) -> 100
A32: 45846 | C32: 30.61 | D32: 19.93 | E32: 31.62 | F32: =100-SUM(C32:E32) -> 17.84 | G32: 10.63 | H32: 10.92 | I32: 49.8 | J32: =100-SUM(G32:I32) -> 28.65 | N32: =100-SUM(K32:M32) -> 100 | R32: =100-SUM(O32:Q32) -> 100 | S32: 36.49 | T32: 40.79 | U32: 0.55 | V32: =100-SUM(S32:U32) -> 22.17 | W32: 33.15 | X32: 33.9 | Y32: 0.4 | Z32: =100-SUM(W32:Y32) -> 32.55 | AD32: =100-SUM(AA32:AC32) -> 100 | AH32: =100-SUM(AE32:AG32) -> 100 | AL32: =100-SUM(AI32:AK32) -> 100 | AP32: =100-SUM(AM32:AO32) -> 100 | AT32: =100-SUM(AQ32:AS32) -> 100
A33: 45847 | C33: 29.87 | D33: 19.65 | E33: 31.68 | F33: =100-SUM(C33:E33) -> 18.8 | G33: 10.97 | H33: 11.01 | I33: 49.17 | J33: =100-SUM(G33:I33) -> 28.85 | N33: =100-SUM(K33:M33) -> 100 | R33: =100-SUM(O33:Q33) -> 100 | S33: 37.36 | T33: 40.54 | U33: 0.49 | V33: =100-SUM(S33:U33) -> 21.61 | W33: 34.15 | X33: 35.06 | Y33: 0.52 | Z33: =100-SUM(W33:Y33) -> 30.27 | AD33: =100-SUM(AA33:AC33) -> 100 | AH33: =100-SUM(AE33:AG33) -> 100 | AL33: =100-SUM(AI33:AK33) -> 100 | AP33: =100-SUM(AM33:AO33) -> 100 | AT33: =100-SUM(AQ33:AS33) -> 100
A34: 45848 | C34: 29.66 | D34: 19.73 | E34: 32.04 | F34: =100-SUM(C34:E34) -> 18.57 | J34: =100-SUM(G34:I34) -> 100 | N34: =100-SUM(K34:M34) -> 100 | R34: =100-SUM(O34:Q34) -> 100 | V34: =100-SUM(S34:U34) -> 100 | Z34: =100-SUM(W34:Y34) -> 100 | AD34: =100-SUM(AA34:AC34) -> 100 | AH34: =100-SUM(AE34:AG34) -> 100 | AI34: 5.39 | AJ34: 0 | AK34: 1.68 | AL34: =100-SUM(AI34:AK34) -> 92.93 | AM34: 2.04 | AN34: - | AO34: 8.2 | AP34: =100-SUM(AM34:AO34) -> 89.76 | AT34: =100-SUM(AQ34:AS34) -> 100
A35: 45849 | F35: =100-SUM(C35:E35) -> 100 | J35: =100-SUM(G35:I35) -> 100 | N35: =100-SUM(K35:M35) -> 100 | R35: =100-SUM(O35:Q35) -> 100 | V35: =100-SUM(S35:U35) -> 100 | Z35: =100-SUM(W35:Y35) -> 100 | AD35: =100-SUM(AA35:AC35) -> 100 | AH35: =100-SUM(AE35:AG35) -> 100 | AL35: =100-SUM(AI35:AK35) -> 100 | AP35: =100-SUM(AM35:AO35) -> 100 | AT35: =100-SUM(AQ35:AS35) -> 100
A36: 45850 | F36: =100-SUM(C36:E36) -> 100 | J36: =100-SUM(G36:I36) -> 100 | N36: =100-SUM(K36:M36) -> 100 | R36: =100-SUM(O36:Q36) -> 100 | V36: =100-SUM(S36:U36) -> 100 | Z36: =100-SUM(W36:Y36) -> 100 | AD36: =100-SUM(AA36:AC36) -> 100 | AH36: =100-SUM(AE36:AG36) -> 100 | AL36: =100-SUM(AI36:AK36) -> 100 | AP36: =100-SUM(AM36:AO36) -> 100 | AT36: =100-SUM(AQ36:AS36) -> 100
A37: 45851 | F37: =100-SUM(C37:E37) -> 100 | J37: =100-SUM(G37:I37) -> 100 | N37: =100-SUM(K37:M37) -> 100 | R37: =100-SUM(O37:Q37) -> 100 | V37: =100-SUM(S37:U37) -> 100 | Z37: =100-SUM(W37:Y37) -> 100 | AD37: =100-SUM(AA37:AC37) -> 100 | AH37: =100-SUM(AE37:AG37) -> 100 | AL37: =100-SUM(AI37:AK37) -> 100 | AP37: =100-SUM(AM37:AO37) -> 100 | AT37: =100-SUM(AQ37:AS37) -> 100
A38: 45852 | F38: =100-SUM(C38:E38) -> 100 | J38: =100-SUM(G38:I38) -> 100 | N38: =100-SUM(K38:M38) -> 100 | R38: =100-SUM(O38:Q38) -> 100 | V38: =100-SUM(S38:U38) -> 100 | Z38: =100-SUM(W38:Y38) -> 100 | AD38: =100-SUM(AA38:AC38) -> 100 | AH38: =100-SUM(AE38:AG38) -> 100 | AL38: =100-SUM(AI38:AK38) -> 100 | AP38: =100-SUM(AM38:AO38) -> 100 | AT38: =100-SUM(AQ38:AS38) -> 100
A39: 45853 | F39: =100-SUM(C39:E39) -> 100 | J39: =100-SUM(G39:I39) -> 100 | N39: =100-SUM(K39:M39) -> 100 | R39: =100-SUM(O39:Q39) -> 100 | V39: =100-SUM(S39:U39) -> 100 | Z39: =100-SUM(W39:Y39) -> 100 | AD39: =100-SUM(AA39:AC39) -> 100 | AH39: =100-SUM(AE39:AG39) -> 100 | AL39: =100-SUM(AI39:AK39) -> 100 | AP39: =100-SUM(AM39:AO39) -> 100 | AT39: =100-SUM(AQ39:AS39) -> 100
A40: 45854 | F40: =100-SUM(C40:E40) -> 100 | J40: =100-SUM(G40:I40) -> 100 | N40: =100-SUM(K40:M40) -> 100 | R40: =100-SUM(O40:Q40) -> 100 | V40: =100-SUM(S40:U40) -> 100 | Z40: =100-SUM(W40:Y40) -> 100 | AD40: =100-SUM(AA40:AC40) -> 100 | AH40: =100-SUM(AE40:AG40) -> 100 | AL40: =100-SUM(AI40:AK40) -> 100 | AP40: =100-SUM(AM40:AO40) -> 100 | AT40: =100-SUM(AQ40:AS40) -> 100
A41: 45855 | B41: 108 | C41: 30.52 | D41: 18.47 | E41: 32.1 | F41: =100-SUM(C41:E41) -> 18.91 | G41: 10.33 | H41: 10.85 | I41: 50.21 | J41: =100-SUM(G41:I41) -> 28.61 | K41: 17.01 | L41: 12.86 | M41: 45.26 | N41: =100-SUM(K41:M41) -> 24.87 | O41: 0.64 | P41: 0.22 | Q41: 66 | R41: =100-SUM(O41:Q41) -> 33.14 | S41: 37.05 | T41: 41.25 | U41: 0 | V41: =100-SUM(S41:U41) -> 21.7 | W41: 32.98 | X41: 34.47 | Y41: 0 | Z41: =100-SUM(W41:Y41) -> 32.55 | AA41: 27.26 | AB41: 11.96 | AC41: 0 | AD41: =100-SUM(AA41:AC41) -> 60.78 | AE41: 17.43 | AF41: 4.9 | AG41: 0 | AH41: =100-SUM(AE41:AG41) -> 77.67 | AI41: 5.55 | AJ41: 1.72 | AK41: 1.39 | AL41: =100-SUM(AI41:AK41) -> 91.34 | AM41: 1.7 | AN41: 0 | AO41: 0 | AP41: =100-SUM(AM41:AO41) -> 98.3 | AQ41: 0.53 | AR41: 0.19 | AS41: 0 | AT41: =100-SUM(AQ41:AS41) -> 99.28
...

Sheet Efficiencies
A1: UREA PLANT ANALYSIS DASHBOARD
B2: UREA REACTOR | G2: STRIPPER | J2: HPD | M2: HPA | O2: LPA | Q2: Remarks
A3: Design Values | B3: 0.58 | C3: 0.37 | D3: 3.11 | E3: 0.52 | F3: 1.899 | G3: 0.78 | H3: 2.01 | I3: 0.52 | J3: 0.654 | K3: 2.41 | L3: 0.55 | M3: 2.38 | N3: 1.289 | O3: 2.29 | P3: 2.28
A4: Date | B4: CO2 Conversion | C4: NH3 Conversion | D4: N/C | E4: H/C | F4: H/U | G4: Efficiency | H4: N/C | I4: H/C | J4: Efficiency | K4: N/C | L4: H/C | M4: N/C | N4: H/C | O4: N/C | P4: H/C
A5: 45819 | B5: =IFERROR(('Lab Analysis'!E4/('Lab Analysis'!E4+(1.364*'Lab Analysis'!D4))),"0") -> 0.56087767 | C5: =IFERROR((2*'Lab Analysis'!E4/60)/('Lab Analysis'!C4/17+(2*'Lab Analysis'!E4/60)),"0") -> 0.37927755 | D5: =IFERROR(((2*('Lab Analysis'!E4/60)+('Lab Analysis'!C4/17))/(('Lab Analysis'!D4/44)+('Lab Analysis'!E4/60))),"0") -> 2.957957 | E5: =IFERROR((('Lab Analysis'!F4/18)-('Lab Analysis'!E4/60))/(('Lab Analysis'!D4/44)+('Lab Analysis'!E4/60)),"0") -> 0.53829996 | F5: =IFERROR((('Lab Analysis'!F4/18)/('Lab Analysis'!E4/60)),"0") -> 1.9596334 | G5: =IFERROR(('Lab Analysis'!I4/('Lab Analysis'!I4+(1.765*'Lab Analysis'!G4))),"0") -> 0 | H5: =IFERROR(((2*('Lab Analysis'!I4/60))+('Lab Analysis'!G4/17))/(('Lab Analysis'!H4/44)+('Lab Analysis'!I4/60)),"0") -> 0 | I5: =IFERROR((('Lab Analysis'!J4/18)-('Lab Analysis'!I4/60))/(('Lab Analysis'!H4/44)+('Lab Analysis'!I4/60)),"0") -> 0 | J5: =IFERROR(('Lab Analysis'!M4/('Lab Analysis'!M4+(1.765*'Lab Analysis'!K4))),"0") -> 0 | K5: =IFERROR(((2*('Lab Analysis'!M4/60))+('Lab Analysis'!K4/17))/(('Lab Analysis'!L4/44)+('Lab Analysis'!M4/60)),"0") -> 0 | L5: =IFERROR((('Lab Analysis'!N4/18)-('Lab Analysis'!M4/60))/(('Lab Analysis'!L4/44)+('Lab Analysis'!M4/60)),"0") -> 0 | M5: =IFERROR(((2*('Lab Analysis'!U4/60))+('Lab Analysis'!S4/17))/(('Lab Analysis'!T4/44)+('Lab Analysis'!U4/60)),"0") -> 0 | N5: =IFERROR((('Lab Analysis'!V4/18)-('Lab Analysis'!U4/60))/(('Lab Analysis'!T4/44)+('Lab Analysis'!U4/60)),"0") -> 0 | O5: =IFERROR(((2*('Lab Analysis'!Y4/60)+('Lab Analysis'!W4/17))/(('Lab Analysis'!X4/44)+('Lab Analysis'!Y4/60))),"0") -> 0 | P5: =IFERROR((('Lab Analysis'!Z4/18)-('Lab Analysis'!Y4/60))/(('Lab Analysis'!X4/44)+('Lab Analysis'!Y4/60)),"0") -> 0
A6: 45820 | B6: =IFERROR(('Lab Analysis'!E5/('Lab Analysis'!E5+(1.364*'Lab Analysis'!D5))),"0") -> 0.55258556 | C6: =IFERROR((2*'Lab Analysis'!E5/60)/('Lab Analysis'!C5/17+(2*'Lab Analysis'!E5/60)),"0") -> 0.37483147 | D6: =IFERROR(((2*('Lab Analysis'!E5/60)+('Lab Analysis'!C5/17))/(('Lab Analysis'!D5/44)+('Lab Analysis'!E5/60))),"0") -> 2.9487998 | E6: =IFERROR((('Lab Analysis'!F5/18)-('Lab Analysis'!E5/60))/(('Lab Analysis'!D5/44)+('Lab Analysis'!E5/60)),"0") -> 0.54722143 | F6: =IFERROR((('Lab Analysis'!F5/18)/('Lab Analysis'!E5/60)),"0") -> 1.9901746 | G6: =IFERROR(('Lab Analysis'!I5/('Lab Analysis'!I5+(1.765*'Lab Analysis'!G5))),"0") -> 0.72508936 | H6: =IFERROR(((2*('Lab Analysis'!I5/60))+('Lab Analysis'!G5/17))/(('Lab Analysis'!H5/44)+('Lab Analysis'!I5/60)),"0") -> 2.1248166 | I6: =IFERROR((('Lab Analysis'!J5/18)-('Lab Analysis'!I5/60))/(('Lab Analysis'!H5/44)+('Lab Analysis'!I5/60)),"0") -> 0.64689988 | J6: =IFERROR(('Lab Analysis'!M5/('Lab Analysis'!M5+(1.765*'Lab Analysis'!K5))),"0") -> 0.59743829 | K6: =IFERROR(((2*('Lab Analysis'!M5/60))+('Lab Analysis'!K5/17))/(('Lab Analysis'!L5/44)+('Lab Analysis'!M5/60)),"0") -> 2.3958083 | L6: =IFERROR((('Lab Analysis'!N5/18)-('Lab Analysis'!M5/60))/(('Lab Analysis'!L5/44)+('Lab Analysis'!M5/60)),"0") -> 0.7861459 | M6: =IFERROR(((2*('Lab Analysis'!U5/60))+('Lab Analysis'!S5/17))/(('Lab Analysis'!T5/44)+('Lab Analysis'!U5/60)),"0") -> 0 | N6: =IFERROR((('Lab Analysis'!V5/18)-('Lab Analysis'!U5/60))/(('Lab Analysis'!T5/44)+('Lab Analysis'!U5/60)),"0") -> 0 | O6: =IFERROR(((2*('Lab Analysis'!Y5/60)+('Lab Analysis'!W5/17))/(('Lab Analysis'!X5/44)+('Lab Analysis'!Y5/60))),"0") -> 0 | P6: =IFERROR((('Lab Analysis'!Z5/18)-('Lab Analysis'!Y5/60))/(('Lab Analysis'!X5/44)+('Lab Analysis'!Y5/60)),"0") -> 0
A7: 45821 | B7: =IFERROR(('Lab Analysis'!E6/('Lab Analysis'!E6+(1.364*'Lab Analysis'!D6))),"0") -> 0.54558798 | C7: =IFERROR((2*'Lab Analysis'!E6/60)/('Lab Analysis'!C6/17+(2*'Lab Analysis'!E6/60)),"0") -> 0.37275638 | D7: =IFERROR(((2*('Lab Analysis'!E6/60)+('Lab Analysis'!C6/17))/(('Lab Analysis'!D6/44)+('Lab Analysis'!E6/60))),"0") -> 2.9276713 | E7: =IFERROR((('Lab Analysis'!F6/18)-('Lab Analysis'!E6/60))/(('Lab Analysis'!D6/44)+('Lab Analysis'!E6/60)),"0") -> 0.53910071 | F7: =IFERROR((('Lab Analysis'!F6/18)/('Lab Analysis'!E6/60)),"0") -> 1.9879899 | G7: =IFERROR(('Lab Analysis'!I6/('Lab Analysis'!I6+(1.765*'Lab Analysis'!G6))),"0") -> 0 | H7: =IFERROR(((2*('Lab Analysis'!I6/60))+('Lab Analysis'!G6/17))/(('Lab Analysis'!H6/44)+('Lab Analysis'!I6/60)),"0") -> 0 | I7: =IFERROR((('Lab Analysis'!J6/18)-('Lab Analysis'!I6/60))/(('Lab Analysis'!H6/44)+('Lab Analysis'!I6/60)),"0") -> 0 | J7: =IFERROR(('Lab Analysis'!M6/('Lab Analysis'!M6+(1.765*'Lab Analysis'!K6))),"0") -> 0 | K7: =IFERROR(((2*('Lab Analysis'!M6/60))+('Lab Analysis'!K6/17))/(('Lab Analysis'!L6/44)+('Lab Analysis'!M6/60)),"0") -> 0 | L7: =IFERROR((('Lab Analysis'!N6/18)-('Lab Analysis'!M6/60))/(('Lab Analysis'!L6/44)+('Lab Analysis'!M6/60)),"0") -> 0 | M7: =IFERROR(((2*('Lab Analysis'!U6/60))+('Lab Analysis'!S6/17))/(('Lab Analysis'!T6/44)+('Lab Analysis'!U6/60)),"0") -> 0 | N7: =IFERROR((('Lab Analysis'!V6/18)-('Lab Analysis'!U6/60))/(('Lab Analysis'!T6/44)+('Lab Analysis'!U6/60)),"0") -> 0 | O7: =IFERROR(((2*('Lab Analysis'!Y6/60)+('Lab Analysis'!W6/17))/(('Lab Analysis'!X6/44)+('Lab Analysis'!Y6/60))),"0") -> 0 | P7: =IFERROR((('Lab Analysis'!Z6/18)-('Lab Analysis'!Y6/60))/(('Lab Analysis'!X6/44)+('Lab Analysis'!Y6/60)),"0") -> 0
A8: 45822 | B8: =IFERROR(('Lab Analysis'!E7/('Lab Analysis'!E7+(1.364*'Lab Analysis'!D7))),"0") -> 0 | C8: =IFERROR((2*'Lab Analysis'!E7/60)/('Lab Analysis'!C7/17+(2*'Lab Analysis'!E7/60)),"0") -> 0 | D8: =IFERROR(((2*('Lab Analysis'!E7/60)+('Lab Analysis'!C7/17))/(('Lab Analysis'!D7/44)+('Lab Analysis'!E7/60))),"0") -> 0 | E8: =IFERROR((('Lab Analysis'!F7/18)-('Lab Analysis'!E7/60))/(('Lab Analysis'!D7/44)+('Lab Analysis'!E7/60)),"0") -> 0 | F8: =IFERROR((('Lab Analysis'!F7/18)/('Lab Analysis'!E7/60)),"0") -> 0 | G8: =IFERROR(('Lab Analysis'!I7/('Lab Analysis'!I7+(1.765*'Lab Analysis'!G7))),"0") -> 0 | H8: =IFERROR(((2*('Lab Analysis'!I7/60))+('Lab Analysis'!G7/17))/(('Lab Analysis'!H7/44)+('Lab Analysis'!I7/60)),"0") -> 0 | I8: =IFERROR((('Lab Analysis'!J7/18)-('Lab Analysis'!I7/60))/(('Lab Analysis'!H7/44)+('Lab Analysis'!I7/60)),"0") -> 0 | J8: =IFERROR(('Lab Analysis'!M7/('Lab Analysis'!M7+(1.765*'Lab Analysis'!K7))),"0") -> 0 | K8: =IFERROR(((2*('Lab Analysis'!M7/60))+('Lab Analysis'!K7/17))/(('Lab Analysis'!L7/44)+('Lab Analysis'!M7/60)),"0") -> 0 | L8: =IFERROR((('Lab Analysis'!N7/18)-('Lab Analysis'!M7/60))/(('Lab Analysis'!L7/44)+('Lab Analysis'!M7/60)),"0") -> 0 | M8: =IFERROR(((2*('Lab Analysis'!U7/60))+('Lab Analysis'!S7/17))/(('Lab Analysis'!T7/44)+('Lab Analysis'!U7/60)),"0") -> 0 | N8: =IFERROR((('Lab Analysis'!V7/18)-('Lab Analysis'!U7/60))/(('Lab Analysis'!T7/44)+('Lab Analysis'!U7/60)),"0") -> 0 | O8: =IFERROR(((2*('Lab Analysis'!Y7/60)+('Lab Analysis'!W7/17))/(('Lab Analysis'!X7/44)+('Lab Analysis'!Y7/60))),"0") -> 0 | P8: =IFERROR((('Lab Analysis'!Z7/18)-('Lab Analysis'!Y7/60))/(('Lab Analysis'!X7/44)+('Lab Analysis'!Y7/60)),"0") -> 0
A9: 45823 | B9: =IFERROR(('Lab Analysis'!E8/('Lab Analysis'!E8+(1.364*'Lab Analysis'!D8))),"0") -> 0 | C9: =IFERROR((2*'Lab Analysis'!E8/60)/('Lab Analysis'!C8/17+(2*'Lab Analysis'!E8/60)),"0") -> 0 | D9: =IFERROR(((2*('Lab Analysis'!E8/60)+('Lab Analysis'!C8/17))/(('Lab Analysis'!D8/44)+('Lab Analysis'!E8/60))),"0") -> 0 | E9: =IFERROR((('Lab Analysis'!F8/18)-('Lab Analysis'!E8/60))/(('Lab Analysis'!D8/44)+('Lab Analysis'!E8/60)),"0") -> 0 | F9: =IFERROR((('Lab Analysis'!F8/18)/('Lab Analysis'!E8/60)),"0") -> 0 | G9: =IFERROR(('Lab Analysis'!I8/('Lab Analysis'!I8+(1.765*'Lab Analysis'!G8))),"0") -> 0 | H9: =IFERROR(((2*('Lab Analysis'!I8/60))+('Lab Analysis'!G8/17))/(('Lab Analysis'!H8/44)+('Lab Analysis'!I8/60)),"0") -> 0 | I9: =IFERROR((('Lab Analysis'!J8/18)-('Lab Analysis'!I8/60))/(('Lab Analysis'!H8/44)+('Lab Analysis'!I8/60)),"0") -> 0 | J9: =IFERROR(('Lab Analysis'!M8/('Lab Analysis'!M8+(1.765*'Lab Analysis'!K8))),"0") -> 0 | K9: =IFERROR(((2*('Lab Analysis'!M8/60))+('Lab Analysis'!K8/17))/(('Lab Analysis'!L8/44)+('Lab Analysis'!M8/60)),"0") -> 0 | L9: =IFERROR((('Lab Analysis'!N8/18)-('Lab Analysis'!M8/60))/(('Lab Analysis'!L8/44)+('Lab Analysis'!M8/60)),"0") -> 0 | M9: =IFERROR(((2*('Lab Analysis'!U8/60))+('Lab Analysis'!S8/17))/(('Lab Analysis'!T8/44)+('Lab Analysis'!U8/60)),"0") -> 0 | N9: =IFERROR((('Lab Analysis'!V8/18)-('Lab Analysis'!U8/60))/(('Lab Analysis'!T8/44)+('Lab Analysis'!U8/60)),"0") -> 0 | O9: =IFERROR(((2*('Lab Analysis'!Y8/60)+('Lab Analysis'!W8/17))/(('Lab Analysis'!X8/44)+('Lab Analysis'!Y8/60))),"0") -> 0 | P9: =IFERROR((('Lab Analysis'!Z8/18)-('Lab Analysis'!Y8/60))/(('Lab Analysis'!X8/44)+('Lab Analysis'!Y8/60)),"0") -> 0
A10: 45824 | B10: =IFERROR(('Lab Analysis'!E9/('Lab Analysis'!E9+(1.364*'Lab Analysis'!D9))),"0") -> 0.53433276 | C10: =IFERROR((2*'Lab Analysis'!E9/60)/('Lab Analysis'!C9/17+(2*'Lab Analysis'!E9/60)),"0") -> 0.36513393 | D10: =IFERROR(((2*('Lab Analysis'!E9/60)+('Lab Analysis'!C9/17))/(('Lab Analysis'!D9/44)+('Lab Analysis'!E9/60))),"0") -> 2.9271402 | E10: =IFERROR((('Lab Analysis'!F9/18)-('Lab Analysis'!E9/60))/(('Lab Analysis'!D9/44)+('Lab Analysis'!E9/60)),"0") -> 0.49311603 | F10: =IFERROR((('Lab Analysis'!F9/18)/('Lab Analysis'!E9/60)),"0") -> 1.9227486 | G10: =IFERROR(('Lab Analysis'!I9/('Lab Analysis'!I9+(1.765*'Lab Analysis'!G9))),"0") -> 0.71879041 | H10: =IFERROR(((2*('Lab Analysis'!I9/60))+('Lab Analysis'!G9/17))/(('Lab Analysis'!H9/44)+('Lab Analysis'!I9/60)),"0") -> 2.1319964 | I10: =IFERROR((('Lab Analysis'!J9/18)-('Lab Analysis'!I9/60))/(('Lab Analysis'!H9/44)+('Lab Analysis'!I9/60)),"0") -> 0.7313925 | J10: =IFERROR(('Lab Analysis'!M9/('Lab Analysis'!M9+(1.765*'Lab Analysis'!K9))),"0") -> 0.60149281 | K10: =IFERROR(((2*('Lab Analysis'!M9/60))+('Lab Analysis'!K9/17))/(('Lab Analysis'!L9/44)+('Lab Analysis'!M9/60)),"0") -> 2.370623 | L10: =IFERROR((('Lab Analysis'!N9/18)-('Lab Analysis'!M9/60))/(('Lab Analysis'!L9/44)+('Lab Analysis'!M9/60)),"0") -> 0.74656064 | M10: =IFERROR(((2*('Lab Analysis'!U9/60))+('Lab Analysis'!S9/17))/(('Lab Analysis'!T9/44)+('Lab Analysis'!U9/60)),"0") -> 0 | N10: =IFERROR((('Lab Analysis'!V9/18)-('Lab Analysis'!U9/60))/(('Lab Analysis'!T9/44)+('Lab Analysis'!U9/60)),"0") -> 0 | O10: =IFERROR(((2*('Lab Analysis'!Y9/60)+('Lab Analysis'!W9/17))/(('Lab Analysis'!X9/44)+('Lab Analysis'!Y9/60))),"0") -> 0 | P10: =IFERROR((('Lab Analysis'!Z9/18)-('Lab Analysis'!Y9/60))/(('Lab Analysis'!X9/44)+('Lab Analysis'!Y9/60)),"0") -> 0
A11: 45825 | B11: =IFERROR(('Lab Analysis'!E10/('Lab Analysis'!E10+(1.364*'Lab Analysis'!D10))),"0") -> 0.54443233 | C11: =IFERROR((2*'Lab Analysis'!E10/60)/('Lab Analysis'!C10/17+(2*'Lab Analysis'!E10/60)),"0") -> 0.37094348 | D11: =IFERROR(((2*('Lab Analysis'!E10/60)+('Lab Analysis'!C10/17))/(('Lab Analysis'!D10/44)+('Lab Analysis'!E10/60))),"0") -> 2.9357489 | E11: =IFERROR((('Lab Analysis'!F10/18)-('Lab Analysis'!E10/60))/(('Lab Analysis'!D10/44)+('Lab Analysis'!E10/60)),"0") -> 0.49582437 | F11: =IFERROR((('Lab Analysis'!F10/18)/('Lab Analysis'!E10/60)),"0") -> 1.9106075 | G11: =IFERROR(('Lab Analysis'!I10/('Lab Analysis'!I10+(1.765*'Lab Analysis'!G10))),"0") -> 0 | H11: =IFERROR(((2*('Lab Analysis'!I10/60))+('Lab Analysis'!G10/17))/(('Lab Analysis'!H10/44)+('Lab Analysis'!I10/60)),"0") -> 0 | I11: =IFERROR((('Lab Analysis'!J10/18)-('Lab Analysis'!I10/60))/(('Lab Analysis'!H10/44)+('Lab Analysis'!I10/60)),"0") -> 0 | J11: =IFERROR(('Lab Analysis'!M10/('Lab Analysis'!M10+(1.765*'Lab Analysis'!K10))),"0") -> 0 | K11: =IFERROR(((2*('Lab Analysis'!M10/60))+('Lab Analysis'!K10/17))/(('Lab Analysis'!L10/44)+('Lab Analysis'!M10/60)),"0") -> 0 | L11: =IFERROR((('Lab Analysis'!N10/18)-('Lab Analysis'!M10/60))/(('Lab Analysis'!L10/44)+('Lab Analysis'!M10/60)),"0") -> 0 | M11: =IFERROR(((2*('Lab Analysis'!U10/60))+('Lab Analysis'!S10/17))/(('Lab Analysis'!T10/44)+('Lab Analysis'!U10/60)),"0") -> 0 | N11: =IFERROR((('Lab Analysis'!V10/18)-('Lab Analysis'!U10/60))/(('Lab Analysis'!T10/44)+('Lab Analysis'!U10/60)),"0") -> 0 | O11: =IFERROR(((2*('Lab Analysis'!Y10/60)+('Lab Analysis'!W10/17))/(('Lab Analysis'!X10/44)+('Lab Analysis'!Y10/60))),"0") -> 0 | P11: =IFERROR((('Lab Analysis'!Z10/18)-('Lab Analysis'!Y10/60))/(('Lab Analysis'!X10/44)+('Lab Analysis'!Y10/60)),"0") -> 0
A12: 45826 | B12: =IFERROR(('Lab Analysis'!E11/('Lab Analysis'!E11+(1.364*'Lab Analysis'!D11))),"0") -> 0.54230195 | C12: =IFERROR((2*'Lab Analysis'!E11/60)/('Lab Analysis'!C11/17+(2*'Lab Analysis'!E11/60)),"0") -> 0.37674119 | D12: =IFERROR(((2*('Lab Analysis'!E11/60)+('Lab Analysis'!C11/17))/(('Lab Analysis'!D11/44)+('Lab Analysis'!E11/60))),"0") -> 2.8792611 | E12: =IFERROR((('Lab Analysis'!F11/18)-('Lab Analysis'!E11/60))/(('Lab Analysis'!D11/44)+('Lab Analysis'!E11/60)),"0") -> 0.54659378 | F12: =IFERROR((('Lab Analysis'!F11/18)/('Lab Analysis'!E11/60)),"0") -> 2.0077911 | G12: =IFERROR(('Lab Analysis'!I11/('Lab Analysis'!I11+(1.765*'Lab Analysis'!G11))),"0") -> 0 | H12: =IFERROR(((2*('Lab Analysis'!I11/60))+('Lab Analysis'!G11/17))/(('Lab Analysis'!H11/44)+('Lab Analysis'!I11/60)),"0") -> 0 | I12: =IFERROR((('Lab Analysis'!J11/18)-('Lab Analysis'!I11/60))/(('Lab Analysis'!H11/44)+('Lab Analysis'!I11/60)),"0") -> 0 | J12: =IFERROR(('Lab Analysis'!M11/('Lab Analysis'!M11+(1.765*'Lab Analysis'!K11))),"0") -> 0 | K12: =IFERROR(((2*('Lab Analysis'!M11/60))+('Lab Analysis'!K11/17))/(('Lab Analysis'!L11/44)+('Lab Analysis'!M11/60)),"0") -> 0 | L12: =IFERROR((('Lab Analysis'!N11/18)-('Lab Analysis'!M11/60))/(('Lab Analysis'!L11/44)+('Lab Analysis'!M11/60)),"0") -> 0 | M12: =IFERROR(((2*('Lab Analysis'!U11/60))+('Lab Analysis'!S11/17))/(('Lab Analysis'!T11/44)+('Lab Analysis'!U11/60)),"0") -> 0 | N12: =IFERROR((('Lab Analysis'!V11/18)-('Lab Analysis'!U11/60))/(('Lab Analysis'!T11/44)+('Lab Analysis'!U11/60)),"0") -> 0 | O12: =IFERROR(((2*('Lab Analysis'!Y11/60)+('Lab Analysis'!W11/17))/(('Lab Analysis'!X11/44)+('Lab Analysis'!Y11/60))),"0") -> 0 | P12: =IFERROR((('Lab Analysis'!Z11/18)-('Lab Analysis'!Y11/60))/(('Lab Analysis'!X11/44)+('Lab Analysis'!Y11/60)),"0") -> 0
A13: 45827 | B13: =IFERROR(('Lab Analysis'!E12/('Lab Analysis'!E12+(1.364*'Lab Analysis'!D12))),"0") -> 0.55009441 | C13: =IFERROR((2*'Lab Analysis'!E12/60)/('Lab Analysis'!C12/17+(2*'Lab Analysis'!E12/60)),"0") -> 0.35770812 | D13: =IFERROR(((2*('Lab Analysis'!E12/60)+('Lab Analysis'!C12/17))/(('Lab Analysis'!D12/44)+('Lab Analysis'!E12/60))),"0") -> 3.0760297 | E13: =IFERROR((('Lab Analysis'!F12/18)-('Lab Analysis'!E12/60))/(('Lab Analysis'!D12/44)+('Lab Analysis'!E12/60)),"0") -> 0.59103183 | F13: =IFERROR((('Lab Analysis'!F12/18)/('Lab Analysis'!E12/60)),"0") -> 2.07429 | G13: =IFERROR(('Lab Analysis'!I12/('Lab Analysis'!I12+(1.765*'Lab Analysis'!G12))),"0") -> 0.73781146 | H13: =IFERROR(((2*('Lab Analysis'!I12/60))+('Lab Analysis'!G12/17))/(('Lab Analysis'!H12/44)+('Lab Analysis'!I12/60)),"0") -> 2.1116088 | I13: =IFERROR((('Lab Analysis'!J12/18)-('Lab Analysis'!I12/60))/(('Lab Analysis'!H12/44)+('Lab Analysis'!I12/60)),"0") -> 0.66689874 | J13: =IFERROR(('Lab Analysis'!M12/('Lab Analysis'!M12+(1.765*'Lab Analysis'!K12))),"0") -> 0.59872055 | K13: =IFERROR(((2*('Lab Analysis'!M12/60))+('Lab Analysis'!K12/17))/(('Lab Analysis'!L12/44)+('Lab Analysis'!M12/60)),"0") -> 2.3879875 | L13: =IFERROR((('Lab Analysis'!N12/18)-('Lab Analysis'!M12/60))/(('Lab Analysis'!L12/44)+('Lab Analysis'!M12/60)),"0") -> 0.60770548 | M13: =IFERROR(((2*('Lab Analysis'!U12/60))+('Lab Analysis'!S12/17))/(('Lab Analysis'!T12/44)+('Lab Analysis'!U12/60)),"0") -> 0 | N13: =IFERROR((('Lab Analysis'!V12/18)-('Lab Analysis'!U12/60))/(('Lab Analysis'!T12/44)+('Lab Analysis'!U12/60)),"0") -> 0 | O13: =IFERROR(((2*('Lab Analysis'!Y12/60)+('Lab Analysis'!W12/17))/(('Lab Analysis'!X12/44)+('Lab Analysis'!Y12/60))),"0") -> 0 | P13: =IFERROR((('Lab Analysis'!Z12/18)-('Lab Analysis'!Y12/60))/(('Lab Analysis'!X12/44)+('Lab Analysis'!Y12/60)),"0") -> 0
A14: 45828 | B14: =IFERROR(('Lab Analysis'!E13/('Lab Analysis'!E13+(1.364*'Lab Analysis'!D13))),"0") -> 0.54068077 | C14: =IFERROR((2*'Lab Analysis'!E13/60)/('Lab Analysis'!C13/17+(2*'Lab Analysis'!E13/60)),"0") -> 0.37010979 | D14: =IFERROR(((2*('Lab Analysis'!E13/60)+('Lab Analysis'!C13/17))/(('Lab Analysis'!D13/44)+('Lab Analysis'!E13/60))),"0") -> 2.9220896 | E14: =IFERROR((('Lab Analysis'!F13/18)-('Lab Analysis'!E13/60))/(('Lab Analysis'!D13/44)+('Lab Analysis'!E13/60)),"0") -> 0.5234495 | F14: =IFERROR((('Lab Analysis'!F13/18)/('Lab Analysis'!E13/60)),"0") -> 1.9680119 | G14: =IFERROR(('Lab Analysis'!I13/('Lab Analysis'!I13+(1.765*'Lab Analysis'!G13))),"0") -> 0 | H14: =IFERROR(((2*('Lab Analysis'!I13/60))+('Lab Analysis'!G13/17))/(('Lab Analysis'!H13/44)+('Lab Analysis'!I13/60)),"0") -> 0 | I14: =IFERROR((('Lab Analysis'!J13/18)-('Lab Analysis'!I13/60))/(('Lab Analysis'!H13/44)+('Lab Analysis'!I13/60)),"0") -> 0 | J14: =IFERROR(('Lab Analysis'!M13/('Lab Analysis'!M13+(1.765*'Lab Analysis'!K13))),"0") -> 0 | K14: =IFERROR(((2*('Lab Analysis'!M13/60))+('Lab Analysis'!K13/17))/(('Lab Analysis'!L13/44)+('Lab Analysis'!M13/60)),"0") -> 0 | L14: =IFERROR((('Lab Analysis'!N13/18)-('Lab Analysis'!M13/60))/(('Lab Analysis'!L13/44)+('Lab Analysis'!M13/60)),"0") -> 0 | M14: =IFERROR(((2*('Lab Analysis'!U13/60))+('Lab Analysis'!S13/17))/(('Lab Analysis'!T13/44)+('Lab Analysis'!U13/60)),"0") -> 0 | N14: =IFERROR((('Lab Analysis'!V13/18)-('Lab Analysis'!U13/60))/(('Lab Analysis'!T13/44)+('Lab Analysis'!U13/60)),"0") -> 0 | O14: =IFERROR(((2*('Lab Analysis'!Y13/60)+('Lab Analysis'!W13/17))/(('Lab Analysis'!X13/44)+('Lab Analysis'!Y13/60))),"0") -> 0 | P14: =IFERROR((('Lab Analysis'!Z13/18)-('Lab Analysis'!Y13/60))/(('Lab Analysis'!X13/44)+('Lab Analysis'!Y13/60)),"0") -> 0
A15: 45829 | B15: =IFERROR(('Lab Analysis'!E14/('Lab Analysis'!E14+(1.364*'Lab Analysis'!D14))),"0") -> 0 | C15: =IFERROR((2*'Lab Analysis'!E14/60)/('Lab Analysis'!C14/17+(2*'Lab Analysis'!E14/60)),"0") -> 0 | D15: =IFERROR(((2*('Lab Analysis'!E14/60)+('Lab Analysis'!C14/17))/(('Lab Analysis'!D14/44)+('Lab Analysis'!E14/60))),"0") -> 0 | E15: =IFERROR((('Lab Analysis'!F14/18)-('Lab Analysis'!E14/60))/(('Lab Analysis'!D14/44)+('Lab Analysis'!E14/60)),"0") -> 0 | F15: =IFERROR((('Lab Analysis'!F14/18)/('Lab Analysis'!E14/60)),"0") -> 0 | G15: =IFERROR(('Lab Analysis'!I14/('Lab Analysis'!I14+(1.765*'Lab Analysis'!G14))),"0") -> 0 | H15: =IFERROR(((2*('Lab Analysis'!I14/60))+('Lab Analysis'!G14/17))/(('Lab Analysis'!H14/44)+('Lab Analysis'!I14/60)),"0") -> 0 | I15: =IFERROR((('Lab Analysis'!J14/18)-('Lab Analysis'!I14/60))/(('Lab Analysis'!H14/44)+('Lab Analysis'!I14/60)),"0") -> 0 | J15: =IFERROR(('Lab Analysis'!M14/('Lab Analysis'!M14+(1.765*'Lab Analysis'!K14))),"0") -> 0 | K15: =IFERROR(((2*('Lab Analysis'!M14/60))+('Lab Analysis'!K14/17))/(('Lab Analysis'!L14/44)+('Lab Analysis'!M14/60)),"0") -> 0 | L15: =IFERROR((('Lab Analysis'!N14/18)-('Lab Analysis'!M14/60))/(('Lab Analysis'!L14/44)+('Lab Analysis'!M14/60)),"0") -> 0 | M15: =IFERROR(((2*('Lab Analysis'!U14/60))+('Lab Analysis'!S14/17))/(('Lab Analysis'!T14/44)+('Lab Analysis'!U14/60)),"0") -> 0 | N15: =IFERROR((('Lab Analysis'!V14/18)-('Lab Analysis'!U14/60))/(('Lab Analysis'!T14/44)+('Lab Analysis'!U14/60)),"0") -> 0 | O15: =IFERROR(((2*('Lab Analysis'!Y14/60)+('Lab Analysis'!W14/17))/(('Lab Analysis'!X14/44)+('Lab Analysis'!Y14/60))),"0") -> 0 | P15: =IFERROR((('Lab Analysis'!Z14/18)-('Lab Analysis'!Y14/60))/(('Lab Analysis'!X14/44)+('Lab Analysis'!Y14/60)),"0") -> 0
A16: 45830 | B16: =IFERROR(('Lab Analysis'!E15/('Lab Analysis'!E15+(1.364*'Lab Analysis'!D15))),"0") -> 0 | C16: =IFERROR((2*'Lab Analysis'!E15/60)/('Lab Analysis'!C15/17+(2*'Lab Analysis'!E15/60)),"0") -> 0 | D16: =IFERROR(((2*('Lab Analysis'!E15/60)+('Lab Analysis'!C15/17))/(('Lab Analysis'!D15/44)+('Lab Analysis'!E15/60))),"0") -> 0 | E16: =IFERROR((('Lab Analysis'!F15/18)-('Lab Analysis'!E15/60))/(('Lab Analysis'!D15/44)+('Lab Analysis'!E15/60)),"0") -> 0 | F16: =IFERROR((('Lab Analysis'!F15/18)/('Lab Analysis'!E15/60)),"0") -> 0 | G16: =IFERROR(('Lab Analysis'!I15/('Lab Analysis'!I15+(1.765*'Lab Analysis'!G15))),"0") -> 0 | H16: =IFERROR(((2*('Lab Analysis'!I15/60))+('Lab Analysis'!G15/17))/(('Lab Analysis'!H15/44)+('Lab Analysis'!I15/60)),"0") -> 0 | I16: =IFERROR((('Lab Analysis'!J15/18)-('Lab Analysis'!I15/60))/(('Lab Analysis'!H15/44)+('Lab Analysis'!I15/60)),"0") -> 0 | J16: =IFERROR(('Lab Analysis'!M15/('Lab Analysis'!M15+(1.765*'Lab Analysis'!K15))),"0") -> 0 | K16: =IFERROR(((2*('Lab Analysis'!M15/60))+('Lab Analysis'!K15/17))/(('Lab Analysis'!L15/44)+('Lab Analysis'!M15/60)),"0") -> 0 | L16: =IFERROR((('Lab Analysis'!N15/18)-('Lab Analysis'!M15/60))/(('Lab Analysis'!L15/44)+('Lab Analysis'!M15/60)),"0") -> 0 | M16: =IFERROR(((2*('Lab Analysis'!U15/60))+('Lab Analysis'!S15/17))/(('Lab Analysis'!T15/44)+('Lab Analysis'!U15/60)),"0") -> 0 | N16: =IFERROR((('Lab Analysis'!V15/18)-('Lab Analysis'!U15/60))/(('Lab Analysis'!T15/44)+('Lab Analysis'!U15/60)),"0") -> 0 | O16: =IFERROR(((2*('Lab Analysis'!Y15/60)+('Lab Analysis'!W15/17))/(('Lab Analysis'!X15/44)+('Lab Analysis'!Y15/60))),"0") -> 0 | P16: =IFERROR((('Lab Analysis'!Z15/18)-('Lab Analysis'!Y15/60))/(('Lab Analysis'!X15/44)+('Lab Analysis'!Y15/60)),"0") -> 0
... A21: 45835 | B21: =IFERROR(('Lab Analysis'!E20/('Lab Analysis'!E20+(1.364*'Lab Analysis'!D20))),"0") -> 0.54213146 | C21: =IFERROR((2*'Lab Analysis'!E20/60)/('Lab Analysis'!C20/17+(2*'Lab Analysis'!E20/60)),"0") -> 0.3667263 | D21: =IFERROR(((2*('Lab Analysis'!E20/60)+('Lab Analysis'!C20/17))/(('Lab Analysis'!D20/44)+('Lab Analysis'!E20/60))),"0") -> 2.9569608 | E21: =IFERROR((('Lab Analysis'!F20/18)-('Lab Analysis'!E20/60))/(('Lab Analysis'!D20/44)+('Lab Analysis'!E20/60)),"0") -> 0.64035158 | F21: =IFERROR((('Lab Analysis'!F20/18)/('Lab Analysis'!E20/60)),"0") -> 2.1810298 | G21: =IFERROR(('Lab Analysis'!I20/('Lab Analysis'!I20+(1.765*'Lab Analysis'!G20))),"0") -> 0 | H21: =IFERROR(((2*('Lab Analysis'!I20/60))+('Lab Analysis'!G20/17))/(('Lab Analysis'!H20/44)+('Lab Analysis'!I20/60)),"0") -> 0 | I21: =IFERROR((('Lab Analysis'!J20/18)-('Lab Analysis'!I20/60))/(('Lab Analysis'!H20/44)+('Lab Analysis'!I20/60)),"0") -> 0 | J21: =IFERROR(('Lab Analysis'!M20/('Lab Analysis'!M20+(1.765*'Lab Analysis'!K20))),"0") -> 0 | K21: =IFERROR(((2*('Lab Analysis'!M20/60))+('Lab Analysis'!K20/17))/(('Lab Analysis'!L20/44)+('Lab Analysis'!M20/60)),"0") -> 0 | L21: =IFERROR((('Lab Analysis'!N20/18)-('Lab Analysis'!M20/60))/(('Lab Analysis'!L20/44)+('Lab Analysis'!M20/60)),"0") -> 0 | M21: =IFERROR(((2*('Lab Analysis'!U20/60))+('Lab Analysis'!S20/17))/(('Lab Analysis'!T20/44)+('Lab Analysis'!U20/60)),"0") -> 0 | N21: =IFERROR((('Lab Analysis'!V20/18)-('Lab Analysis'!U20/60))/(('Lab Analysis'!T20/44)+('Lab Analysis'!U20/60)),"0") -> 0 | O21: =IFERROR(((2*('Lab Analysis'!Y20/60)+('Lab Analysis'!W20/17))/(('Lab Analysis'!X20/44)+('Lab Analysis'!Y20/60))),"0") -> 0 | P21: =IFERROR((('Lab Analysis'!Z20/18)-('Lab Analysis'!Y20/60))/(('Lab Analysis'!X20/44)+('Lab Analysis'!Y20/60)),"0") -> 0
A22: 45836 | B22: =IFERROR(('Lab Analysis'!E22/('Lab Analysis'!E22+(1.364*'Lab Analysis'!D22))),"0") -> 0 | C22: =IFERROR((2*'Lab Analysis'!E22/60)/('Lab Analysis'!C22/17+(2*'Lab Analysis'!E22/60)),"0") -> 0 | D22: =IFERROR(((2*('Lab Analysis'!E22/60)+('Lab Analysis'!C22/17))/(('Lab Analysis'!D22/44)+('Lab Analysis'!E22/60))),"0") -> 0 | E22: =IFERROR((('Lab Analysis'!F22/18)-('Lab Analysis'!E22/60))/(('Lab Analysis'!D22/44)+('Lab Analysis'!E22/60)),"0") -> 0 | F22: =IFERROR((('Lab Analysis'!F22/18)/('Lab Analysis'!E22/60)),"0") -> 0 | G22: =IFERROR(('Lab Analysis'!I22/('Lab Analysis'!I22+(1.765*'Lab Analysis'!G22))),"0") -> 0 | H22: =IFERROR(((2*('Lab Analysis'!I22/60))+('Lab Analysis'!G22/17))/(('Lab Analysis'!H22/44)+('Lab Analysis'!I22/60)),"0") -> 0 | I22: =IFERROR((('Lab Analysis'!J22/18)-('Lab Analysis'!I22/60))/(('Lab Analysis'!H22/44)+('Lab Analysis'!I22/60)),"0") -> 0 | J22: =IFERROR(('Lab Analysis'!M22/('Lab Analysis'!M22+(1.765*'Lab Analysis'!K22))),"0") -> 0 | K22: =IFERROR(((2*('Lab Analysis'!M22/60))+('Lab Analysis'!K22/17))/(('Lab Analysis'!L22/44)+('Lab Analysis'!M22/60)),"0") -> 0 | L22: =IFERROR((('Lab Analysis'!N22/18)-('Lab Analysis'!M22/60))/(('Lab Analysis'!L22/44)+('Lab Analysis'!M22/60)),"0") -> 0 | M22: =IFERROR(((2*('Lab Analysis'!U22/60))+('Lab Analysis'!S22/17))/(('Lab Analysis'!T22/44)+('Lab Analysis'!U22/60)),"0") -> 0 | N22: =IFERROR((('Lab Analysis'!V22/18)-('Lab Analysis'!U22/60))/(('Lab Analysis'!T22/44)+('Lab Analysis'!U22/60)),"0") -> 0 | O22: =IFERROR(((2*('Lab Analysis'!Y22/60)+('Lab Analysis'!W22/17))/(('Lab Analysis'!X22/44)+('Lab Analysis'!Y22/60))),"0") -> 0 | P22: =IFERROR((('Lab Analysis'!Z22/18)-('Lab Analysis'!Y22/60))/(('Lab Analysis'!X22/44)+('Lab Analysis'!Y22/60)),"0") -> 0
A23: 45837 | B23: =IFERROR(('Lab Analysis'!E23/('Lab Analysis'!E23+(1.364*'Lab Analysis'!D23))),"0") -> 0 | C23: =IFERROR((2*'Lab Analysis'!E23/60)/('Lab Analysis'!C23/17+(2*'Lab Analysis'!E23/60)),"0") -> 0 | D23: =IFERROR(((2*('Lab Analysis'!E23/60)+('Lab Analysis'!C23/17))/(('Lab Analysis'!D23/44)+('Lab Analysis'!E23/60))),"0") -> 0 | E23: =IFERROR((('Lab Analysis'!F23/18)-('Lab Analysis'!E23/60))/(('Lab Analysis'!D23/44)+('Lab Analysis'!E23/60)),"0") -> 0 | F23: =IFERROR((('Lab Analysis'!F23/18)/('Lab Analysis'!E23/60)),"0") -> 0 | G23: =IFERROR(('Lab Analysis'!I23/('Lab Analysis'!I23+(1.765*'Lab Analysis'!G23))),"0") -> 0 | H23: =IFERROR(((2*('Lab Analysis'!I23/60))+('Lab Analysis'!G23/17))/(('Lab Analysis'!H23/44)+('Lab Analysis'!I23/60)),"0") -> 0 | I23: =IFERROR((('Lab Analysis'!J23/18)-('Lab Analysis'!I23/60))/(('Lab Analysis'!H23/44)+('Lab Analysis'!I23/60)),"0") -> 0 | J23: =IFERROR(('Lab Analysis'!M23/('Lab Analysis'!M23+(1.765*'Lab Analysis'!K23))),"0") -> 0 | K23: =IFERROR(((2*('Lab Analysis'!M23/60))+('Lab Analysis'!K23/17))/(('Lab Analysis'!L23/44)+('Lab Analysis'!M23/60)),"0") -> 0 | L23: =IFERROR((('Lab Analysis'!N23/18)-('Lab Analysis'!M23/60))/(('Lab Analysis'!L23/44)+('Lab Analysis'!M23/60)),"0") -> 0 | M23: =IFERROR(((2*('Lab Analysis'!U23/60))+('Lab Analysis'!S23/17))/(('Lab Analysis'!T23/44)+('Lab Analysis'!U23/60)),"0") -> 0 | N23: =IFERROR((('Lab Analysis'!V23/18)-('Lab Analysis'!U23/60))/(('Lab Analysis'!T23/44)+('Lab Analysis'!U23/60)),"0") -> 0 | O23: =IFERROR(((2*('Lab Analysis'!Y23/60)+('Lab Analysis'!W23/17))/(('Lab Analysis'!X23/44)+('Lab Analysis'!Y23/60))),"0") -> 0 | P23: =IFERROR((('Lab Analysis'!Z23/18)-('Lab Analysis'!Y23/60))/(('Lab Analysis'!X23/44)+('Lab Analysis'!Y23/60)),"0") -> 0
A24: 45838 | B24: =IFERROR(('Lab Analysis'!E24/('Lab Analysis'!E24+(1.364*'Lab Analysis'!D24))),"0") -> 0.54045373 | C24: =IFERROR((2*'Lab Analysis'!E24/60)/('Lab Analysis'!C24/17+(2*'Lab Analysis'!E24/60)),"0") -> 0.3608837 | D24: =IFERROR(((2*('Lab Analysis'!E24/60)+('Lab Analysis'!C24/17))/(('Lab Analysis'!D24/44)+('Lab Analysis'!E24/60))),"0") -> 2.9955354 | E24: =IFERROR((('Lab Analysis'!F24/18)-('Lab Analysis'!E24/60))/(('Lab Analysis'!D24/44)+('Lab Analysis'!E24/60)),"0") -> 0.54599033 | F24: =IFERROR((('Lab Analysis'!F24/18)/('Lab Analysis'!E24/60)),"0") -> 2.0101206 | G24: =IFERROR(('Lab Analysis'!I24/('Lab Analysis'!I24+(1.765*'Lab Analysis'!G24))),"0") -> 0.73540998 | H24: =IFERROR(((2*('Lab Analysis'!I24/60))+('Lab Analysis'!G24/17))/(('Lab Analysis'!H24/44)+('Lab Analysis'!I24/60)),"0") -> 2.1121514 | I24: =IFERROR((('Lab Analysis'!J24/18)-('Lab Analysis'!I24/60))/(('Lab Analysis'!H24/44)+('Lab Analysis'!I24/60)),"0") -> 0.74485242 | J24: =IFERROR(('Lab Analysis'!M24/('Lab Analysis'!M24+(1.765*'Lab Analysis'!K24))),"0") -> 0.59991587 | K24: =IFERROR(((2*('Lab Analysis'!M24/60))+('Lab Analysis'!K24/17))/(('Lab Analysis'!L24/44)+('Lab Analysis'!M24/60)),"0") -> 2.3845231 | L24: =IFERROR((('Lab Analysis'!N24/18)-('Lab Analysis'!M24/60))/(('Lab Analysis'!L24/44)+('Lab Analysis'!M24/60)),"0") -> 0.62808765 | M24: =IFERROR(((2*('Lab Analysis'!U24/60))+('Lab Analysis'!S24/17))/(('Lab Analysis'!T24/44)+('Lab Analysis'!U24/60)),"0") -> 2.3714641 | N24: =IFERROR((('Lab Analysis'!V24/18)-('Lab Analysis'!U24/60))/(('Lab Analysis'!T24/44)+('Lab Analysis'!U24/60)),"0") -> 1.4638386 | O24: =IFERROR(((2*('Lab Analysis'!Y24/60)+('Lab Analysis'!W24/17))/(('Lab Analysis'!X24/44)+('Lab Analysis'!Y24/60))),"0") -> 2.5622919 | P24: =IFERROR((('Lab Analysis'!Z24/18)-('Lab Analysis'!Y24/60))/(('Lab Analysis'!X24/44)+('Lab Analysis'!Y24/60)),"0") -> 2.3421122
A25: 45839 | B25: =IFERROR(('Lab Analysis'!E25/('Lab Analysis'!E25+(1.364*'Lab Analysis'!D25))),"0") -> 0.54482552 | C25: =IFERROR((2*'Lab Analysis'!E25/60)/('Lab Analysis'!C25/17+(2*'Lab Analysis'!E25/60)),"0") -> 0.37096097 | D25: =IFERROR(((2*('Lab Analysis'!E25/60)+('Lab Analysis'!C25/17))/(('Lab Analysis'!D25/44)+('Lab Analysis'!E25/60))),"0") -> 2.9377303 | E25: =IFERROR((('Lab Analysis'!F25/18)-('Lab Analysis'!E25/60))/(('Lab Analysis'!D25/44)+('Lab Analysis'!E25/60)),"0") -> 0.60252441 | F25: =IFERROR((('Lab Analysis'!F25/18)/('Lab Analysis'!E25/60)),"0") -> 2.1057692 | G25: =IFERROR(('Lab Analysis'!I25/('Lab Analysis'!I25+(1.765*'Lab Analysis'!G25))),"0") -> 0 | H25: =IFERROR(((2*('Lab Analysis'!I25/60))+('Lab Analysis'!G25/17))/(('Lab Analysis'!H25/44)+('Lab Analysis'!I25/60)),"0") -> 0 | I25: =IFERROR((('Lab Analysis'!J25/18)-('Lab Analysis'!I25/60))/(('Lab Analysis'!H25/44)+('Lab Analysis'!I25/60)),"0") -> 0 | J25: =IFERROR(('Lab Analysis'!M25/('Lab Analysis'!M25+(1.765*'Lab Analysis'!K25))),"0") -> 0 | K25: =IFERROR(((2*('Lab Analysis'!M25/60))+('Lab Analysis'!K25/17))/(('Lab Analysis'!L25/44)+('Lab Analysis'!M25/60)),"0") -> 0 | L25: =IFERROR((('Lab Analysis'!N25/18)-('Lab Analysis'!M25/60))/(('Lab Analysis'!L25/44)+('Lab Analysis'!M25/60)),"0") -> 0 | M25: =IFERROR(((2*('Lab Analysis'!U25/60))+('Lab Analysis'!S25/17))/(('Lab Analysis'!T25/44)+('Lab Analysis'!U25/60)),"0") -> 0 | N25: =IFERROR((('Lab Analysis'!V25/18)-('Lab Analysis'!U25/60))/(('Lab Analysis'!T25/44)+('Lab Analysis'!U25/60)),"0") -> 0 | O25: =IFERROR(((2*('Lab Analysis'!Y25/60)+('Lab Analysis'!W25/17))/(('Lab Analysis'!X25/44)+('Lab Analysis'!Y25/60))),"0") -> 0 | P25: =IFERROR((('Lab Analysis'!Z25/18)-('Lab Analysis'!Y25/60))/(('Lab Analysis'!X25/44)+('Lab Analysis'!Y25/60)),"0") -> 0
A26: 45840 | B26: =IFERROR(('Lab Analysis'!E26/('Lab Analysis'!E26+(1.364*'Lab Analysis'!D26))),"0") -> 0.53854982 | C26: =IFERROR((2*'Lab Analysis'!E26/60)/('Lab Analysis'!C26/17+(2*'Lab Analysis'!E26/60)),"0") -> 0.37321937 | D26: =IFERROR(((2*('Lab Analysis'!E26/60)+('Lab Analysis'!C26/17))/(('Lab Analysis'!D26/44)+('Lab Analysis'!E26/60))),"0") -> 2.8863243 | E26: =IFERROR((('Lab Analysis'!F26/18)-('Lab Analysis'!E26/60))/(('Lab Analysis'!D26/44)+('Lab Analysis'!E26/60)),"0") -> 0.54010082 | F26: =IFERROR((('Lab Analysis'!F26/18)/('Lab Analysis'!E26/60)),"0") -> 2.0027566 | G26: =IFERROR(('Lab Analysis'!I26/('Lab Analysis'!I26+(1.765*'Lab Analysis'!G26))),"0") -> 0 | H26: =IFERROR(((2*('Lab Analysis'!I26/60))+('Lab Analysis'!G26/17))/(('Lab Analysis'!H26/44)+('Lab Analysis'!I26/60)),"0") -> 0 | I26: =IFERROR((('Lab Analysis'!J26/18)-('Lab Analysis'!I26/60))/(('Lab Analysis'!H26/44)+('Lab Analysis'!I26/60)),"0") -> 0 | J26: =IFERROR(('Lab Analysis'!M26/('Lab Analysis'!M26+(1.765*'Lab Analysis'!K26))),"0") -> 0 | K26: =IFERROR(((2*('Lab Analysis'!M26/60))+('Lab Analysis'!K26/17))/(('Lab Analysis'!L26/44)+('Lab Analysis'!M26/60)),"0") -> 0 | L26: =IFERROR((('Lab Analysis'!N26/18)-('Lab Analysis'!M26/60))/(('Lab Analysis'!L26/44)+('Lab Analysis'!M26/60)),"0") -> 0 | M26: =IFERROR(((2*('Lab Analysis'!U26/60))+('Lab Analysis'!S26/17))/(('Lab Analysis'!T26/44)+('Lab Analysis'!U26/60)),"0") -> 0 | N26: =IFERROR((('Lab Analysis'!V26/18)-('Lab Analysis'!U26/60))/(('Lab Analysis'!T26/44)+('Lab Analysis'!U26/60)),"0") -> 0 | O26: =IFERROR(((2*('Lab Analysis'!Y26/60)+('Lab Analysis'!W26/17))/(('Lab Analysis'!X26/44)+('Lab Analysis'!Y26/60))),"0") -> 0 | P26: =IFERROR((('Lab Analysis'!Z26/18)-('Lab Analysis'!Y26/60))/(('Lab Analysis'!X26/44)+('Lab Analysis'!Y26/60)),"0") -> 0
A27: 45841 | B27: =IFERROR(('Lab Analysis'!E27/('Lab Analysis'!E27+(1.364*'Lab Analysis'!D27))),"0") -> 0.54157327 | C27: =IFERROR((2*'Lab Analysis'!E27/60)/('Lab Analysis'!C27/17+(2*'Lab Analysis'!E27/60)),"0") -> 0.36755252 | D27: =IFERROR(((2*('Lab Analysis'!E27/60)+('Lab Analysis'!C27/17))/(('Lab Analysis'!D27/44)+('Lab Analysis'!E27/60))),"0") -> 2.9472766 | E27: =IFERROR((('Lab Analysis'!F27/18)-('Lab Analysis'!E27/60))/(('Lab Analysis'!D27/44)+('Lab Analysis'!E27/60)),"0") -> 0.471085 | F27: =IFERROR((('Lab Analysis'!F27/18)/('Lab Analysis'!E27/60)),"0") -> 1.8697391 | G27: =IFERROR(('Lab Analysis'!I27/('Lab Analysis'!I27+(1.765*'Lab Analysis'!G27))),"0") -> 0.74098571 | H27: =IFERROR(((2*('Lab Analysis'!I27/60))+('Lab Analysis'!G27/17))/(('Lab Analysis'!H27/44)+('Lab Analysis'!I27/60)),"0") -> 2.1039279 | I27: =IFERROR((('Lab Analysis'!J27/18)-('Lab Analysis'!I27/60))/(('Lab Analysis'!H27/44)+('Lab Analysis'!I27/60)),"0") -> 0.74566531 | J27: =IFERROR(('Lab Analysis'!M27/('Lab Analysis'!M27+(1.765*'Lab Analysis'!K27))),"0") -> 0.60061144 | K27: =IFERROR(((2*('Lab Analysis'!M27/60))+('Lab Analysis'!K27/17))/(('Lab Analysis'!L27/44)+('Lab Analysis'!M27/60)),"0") -> 2.3883988 | L27: =IFERROR((('Lab Analysis'!N27/18)-('Lab Analysis'!M27/60))/(('Lab Analysis'!L27/44)+('Lab Analysis'!M27/60)),"0") -> 0.62380876 | M27: =IFERROR(((2*('Lab Analysis'!U27/60))+('Lab Analysis'!S27/17))/(('Lab Analysis'!T27/44)+('Lab Analysis'!U27/60)),"0") -> 2.3961777 | N27: =IFERROR((('Lab Analysis'!V27/18)-('Lab Analysis'!U27/60))/(('Lab Analysis'!T27/44)+('Lab Analysis'!U27/60)),"0") -> 1.4204618 | O27: =IFERROR(((2*('Lab Analysis'!Y27/60)+('Lab Analysis'!W27/17))/(('Lab Analysis'!X27/44)+('Lab Analysis'!Y27/60))),"0") -> 2.5616464 | P27: =IFERROR((('Lab Analysis'!Z27/18)-('Lab Analysis'!Y27/60))/(('Lab Analysis'!X27/44)+('Lab Analysis'!Y27/60)),"0") -> 2.3109937
A28: 45842 | B28: =IFERROR(('Lab Analysis'!E28/('Lab Analysis'!E28+(1.364*'Lab Analysis'!D28))),"0") -> 0.55346618 | C28: =IFERROR((2*'Lab Analysis'!E28/60)/('Lab Analysis'!C28/17+(2*'Lab Analysis'!E28/60)),"0") -> 0.36228078 | D28: =IFERROR(((2*('Lab Analysis'!E28/60)+('Lab Analysis'!C28/17))/(('Lab Analysis'!D28/44)+('Lab Analysis'!E28/60))),"0") -> 3.0558181 | E28: =IFERROR((('Lab Analysis'!F28/18)-('Lab Analysis'!E28/60))/(('Lab Analysis'!D28/44)+('Lab Analysis'!E28/60)),"0") -> 0.44087494 | F28: =IFERROR((('Lab Analysis'!F28/18)/('Lab Analysis'!E28/60)),"0") -> 1.7964759 | G28: =IFERROR(('Lab Analysis'!I28/('Lab Analysis'!I28+(1.765*'Lab Analysis'!G28))),"0") -> 0 | H28: =IFERROR(((2*('Lab Analysis'!I28/60))+('Lab Analysis'!G28/17))/(('Lab Analysis'!H28/44)+('Lab Analysis'!I28/60)),"0") -> 0 | I28: =IFERROR((('Lab Analysis'!J28/18)-('Lab Analysis'!I28/60))/(('Lab Analysis'!H28/44)+('Lab Analysis'!I28/60)),"0") -> 0 | J28: =IFERROR(('Lab Analysis'!M28/('Lab Analysis'!M28+(1.765*'Lab Analysis'!K28))),"0") -> 0 | K28: =IFERROR(((2*('Lab Analysis'!M28/60))+('Lab Analysis'!K28/17))/(('Lab Analysis'!L28/44)+('Lab Analysis'!M28/60)),"0") -> 0 | L28: =IFERROR((('Lab Analysis'!N28/18)-('Lab Analysis'!M28/60))/(('Lab Analysis'!L28/44)+('Lab Analysis'!M28/60)),"0") -> 0 | M28: =IFERROR(((2*('Lab Analysis'!U28/60))+('Lab Analysis'!S28/17))/(('Lab Analysis'!T28/44)+('Lab Analysis'!U28/60)),"0") -> 0 | N28: =IFERROR((('Lab Analysis'!V28/18)-('Lab Analysis'!U28/60))/(('Lab Analysis'!T28/44)+('Lab Analysis'!U28/60)),"0") -> 0 | O28: =IFERROR(((2*('Lab Analysis'!Y28/60)+('Lab Analysis'!W28/17))/(('Lab Analysis'!X28/44)+('Lab Analysis'!Y28/60))),"0") -> 0 | P28: =IFERROR((('Lab Analysis'!Z28/18)-('Lab Analysis'!Y28/60))/(('Lab Analysis'!X28/44)+('Lab Analysis'!Y28/60)),"0") -> 0
A29: 45843 | B29: =IFERROR(('Lab Analysis'!E29/('Lab Analysis'!E29+(1.364*'Lab Analysis'!D29))),"0") -> 0 | C29: =IFERROR((2*'Lab Analysis'!E29/60)/('Lab Analysis'!C29/17+(2*'Lab Analysis'!E29/60)),"0") -> 0 | D29: =IFERROR(((2*('Lab Analysis'!E29/60)+('Lab Analysis'!C29/17))/(('Lab Analysis'!D29/44)+('Lab Analysis'!E29/60))),"0") -> 0 | E29: =IFERROR((('Lab Analysis'!F29/18)-('Lab Analysis'!E29/60))/(('Lab Analysis'!D29/44)+('Lab Analysis'!E29/60)),"0") -> 0 | F29: =IFERROR((('Lab Analysis'!F29/18)/('Lab Analysis'!E29/60)),"0") -> 0 | G29: =IFERROR(('Lab Analysis'!I29/('Lab Analysis'!I29+(1.765*'Lab Analysis'!G29))),"0") -> 0 | H29: =IFERROR(((2*('Lab Analysis'!I29/60))+('Lab Analysis'!G29/17))/(('Lab Analysis'!H29/44)+('Lab Analysis'!I29/60)),"0") -> 0 | I29: =IFERROR((('Lab Analysis'!J29/18)-('Lab Analysis'!I29/60))/(('Lab Analysis'!H29/44)+('Lab Analysis'!I29/60)),"0") -> 0 | J29: =IFERROR(('Lab Analysis'!M29/('Lab Analysis'!M29+(1.765*'Lab Analysis'!K29))),"0") -> 0 | K29: =IFERROR(((2*('Lab Analysis'!M29/60))+('Lab Analysis'!K29/17))/(('Lab Analysis'!L29/44)+('Lab Analysis'!M29/60)),"0") -> 0 | L29: =IFERROR((('Lab Analysis'!N29/18)-('Lab Analysis'!M29/60))/(('Lab Analysis'!L29/44)+('Lab Analysis'!M29/60)),"0") -> 0 | M29: =IFERROR(((2*('Lab Analysis'!U29/60))+('Lab Analysis'!S29/17))/(('Lab Analysis'!T29/44)+('Lab Analysis'!U29/60)),"0") -> 0 | N29: =IFERROR((('Lab Analysis'!V29/18)-('Lab Analysis'!U29/60))/(('Lab Analysis'!T29/44)+('Lab Analysis'!U29/60)),"0") -> 0 | O29: =IFERROR(((2*('Lab Analysis'!Y29/60)+('Lab Analysis'!W29/17))/(('Lab Analysis'!X29/44)+('Lab Analysis'!Y29/60))),"0") -> 0 | P29: =IFERROR((('Lab Analysis'!Z29/18)-('Lab Analysis'!Y29/60))/(('Lab Analysis'!X29/44)+('Lab Analysis'!Y29/60)),"0") -> 0
A30: 45844 | B30: =IFERROR(('Lab Analysis'!E30/('Lab Analysis'!E30+(1.364*'Lab Analysis'!D30))),"0") -> 0 | C30: =IFERROR((2*'Lab Analysis'!E30/60)/('Lab Analysis'!C30/17+(2*'Lab Analysis'!E30/60)),"0") -> 0 | D30: =IFERROR(((2*('Lab Analysis'!E30/60)+('Lab Analysis'!C30/17))/(('Lab Analysis'!D30/44)+('Lab Analysis'!E30/60))),"0") -> 0 | E30: =IFERROR((('Lab Analysis'!F30/18)-('Lab Analysis'!E30/60))/(('Lab Analysis'!D30/44)+('Lab Analysis'!E30/60)),"0") -> 0 | F30: =IFERROR((('Lab Analysis'!F30/18)/('Lab Analysis'!E30/60)),"0") -> 0 | G30: =IFERROR(('Lab Analysis'!I30/('Lab Analysis'!I30+(1.765*'Lab Analysis'!G30))),"0") -> 0 | H30: =IFERROR(((2*('Lab Analysis'!I30/60))+('Lab Analysis'!G30/17))/(('Lab Analysis'!H30/44)+('Lab Analysis'!I30/60)),"0") -> 0 | I30: =IFERROR((('Lab Analysis'!J30/18)-('Lab Analysis'!I30/60))/(('Lab Analysis'!H30/44)+('Lab Analysis'!I30/60)),"0") -> 0 | J30: =IFERROR(('Lab Analysis'!M30/('Lab Analysis'!M30+(1.765*'Lab Analysis'!K30))),"0") -> 0 | K30: =IFERROR(((2*('Lab Analysis'!M30/60))+('Lab Analysis'!K30/17))/(('Lab Analysis'!L30/44)+('Lab Analysis'!M30/60)),"0") -> 0 | L30: =IFERROR((('Lab Analysis'!N30/18)-('Lab Analysis'!M30/60))/(('Lab Analysis'!L30/44)+('Lab Analysis'!M30/60)),"0") -> 0 | M30: =IFERROR(((2*('Lab Analysis'!U30/60))+('Lab Analysis'!S30/17))/(('Lab Analysis'!T30/44)+('Lab Analysis'!U30/60)),"0") -> 0 | N30: =IFERROR((('Lab Analysis'!V30/18)-('Lab Analysis'!U30/60))/(('Lab Analysis'!T30/44)+('Lab Analysis'!U30/60)),"0") -> 0 | O30: =IFERROR(((2*('Lab Analysis'!Y30/60)+('Lab Analysis'!W30/17))/(('Lab Analysis'!X30/44)+('Lab Analysis'!Y30/60))),"0") -> 0 | P30: =IFERROR((('Lab Analysis'!Z30/18)-('Lab Analysis'!Y30/60))/(('Lab Analysis'!X30/44)+('Lab Analysis'!Y30/60)),"0") -> 0
